Workbook

Sheet 1.ร้านโชห่วย✅ (2)
A1: รายงานจดรับ-จ่าย : มกราคม 2568
A2: ชื่อสถานประกอบการ (ชื่อร้าน) : ร้านขายดี | C2: สถานะ : จด VAT
A3: เลขผู้เสียภาษีอากร : 3 9355 66000 69 1
A5: ว/ด/ป | B5: รายการ | C5: รายรับ | F5: รายจ่าย | L5: VAT ซื้อ | N5: เอกสาร
C6: หน้าร้าน | D6: VAT ขาย | F6: ซื้อจากห้าง | G6: ซื้อจากตลาด/ร้านค้าส่ง | H6: ค่าแรง | I6: สาธารณูปโภค | J6: อื่นๆ | N6: บิลค่าใช้จ่าย
A7: 243984 | B7: ซื้อของ จาก Makro | F7: 346450 | L7: =F7*7/107 -> 22664.953 | N7: บิลสมบูรณ์
B8: ซื้อของ จาก ร้านน้องดาว ขายส่ง | G8: 124650 | N8: ใบสำคัญรับเงิน
B9: ซื้อของ จาก ตลาดสดในเมือง | G9: 2400 | N9: บิลเงินสด+ใบรับรองแทนใบเสร็จรับเงิน
B10: ซื้อถุงพลาสติกใส ถุงก็อปแก็ป | J10: 1500 | N10: บิลเงินสด+ใบรับรองแทนใบเสร็จรับเงิน
B11: จ่ายเงินเดือน ประจำเดือน ธ.ค.66 | H11: 150000 | N11: ใบทะเบียนเงินเดือน
B12: สรุปรายได้ประจำวันจากการขายหน้าร้าน | C12: 200000 | D12: =C12*7/107 -> 13084.112 | N12: รายงานยอดขายประจำวัน
A13: 243985 | B13: ซื้อของ จาก Lotus's | F13: 43080 | L13: =F13*7/107 -> 2818.3178 | N13: บิลสมบูรณ์
B14: ซื้อน้ำแข็ง | J14: 2200 | N14: บิลเงินสด+ใบรับรองแทนใบเสร็จรับเงิน
B15: สรุปรายได้ประจำวันจากการขายหน้าร้าน | C15: 150000 | D15: =C15*7/107 -> 9813.0841 | N15: รายงานยอดขายประจำวัน
A16: 243986 | B16: ซื้อของ จาก Big C | F16: 13520 | L16: =F16*7/107 -> 884.48598 | N16: บิลสมบูรณ์
B17: สรุปรายได้ประจำวันจากการขายหน้าร้าน | C17: 150000 | D17: =C17*7/107 -> 9813.0841 | N17: รายงานยอดขายประจำวัน
A18: 243987 | B18: ซื้อของ จาก Makro | F18: 40970 | L18: =F18*7/107 -> 2680.2804 | N18: บิลสมบูรณ์
B19: ซื้อน้ำแข็ง | J19: 1500 | N19: บิลเงินสด+ใบรับรองแทนใบเสร็จรับเงิน
B20: เรียกรถไปส่งของให้ลูกค้า | J20: 400 | N20: ใบรับรองแทนใบเสร็จรับเงิน
B21: สรุปรายได้ประจำวันจากการขายหน้าร้าน | C21: 180000 | D21: =C21*7/107 -> 11775.701 | N21: รายงานยอดขายประจำวัน
A22: 243988 | B22: ซื้อของ จาก ตลาดสดในเมือง | G22: 850 | N22: บิลเงินสด+ใบรับรองแทนใบเสร็จรับเงิน
B23: จ่ายค่าไฟ เดือน ธ.ค.66 | I23: 13555.8 | L23: =I23*7/107 -> 886.82804 | N23: บิลสมบูรณ์
B24: จ่ายค่าน้ำ เดือน ธ.ค.66 | I24: 209.72 | L24: =I24*7/107 -> 13.72 | N24: บิลสมบูรณ์
B25: สรุปรายได้ประจำวันจากการขายหน้าร้าน | C25: 80000 | D25: =C25*7/107 -> 5233.6449 | N25: รายงานยอดขายประจำวัน
A26: 243989 | B26: ซื้อของ จาก ร้านพอลลี่ แก๊ส | G26: 64500 | N26: ใบสำคัญรับเงิน
B27: ซื้อถุงพลาสติกใส ถุงก็อปแก็ป | J27: 1000 | N27: บิลเงินสด+ใบรับรองแทนใบเสร็จรับเงิน
B28: สรุปรายได้ประจำวันจากการขายหน้าร้าน | C28: 70000 | D28: =C28*7/107 -> 4579.4393 | N28: รายงานยอดขายประจำวัน
A29: 243990 | B29: ซื้อของ จาก Lotus's | F29: 5055 | L29: =F29*7/107 -> 330.70093 | N29: บิลสมบูรณ์
B30: ซื้อน้ำแข็ง | J30: 1300 | N30: บิลเงินสด+ใบรับรองแทนใบเสร็จรับเงิน
B31: สรุปรายได้ประจำวันจากการขายหน้าร้าน | C31: 90000 | D31: =C31*7/107 -> 5887.8505 | N31: รายงานยอดขายประจำวัน
A32: 243991 | B32: ซื้อของ จาก Big C | F32: 4520 | L32: =F32*7/107 -> 295.70093 | N32: บิลสมบูรณ์
B33: สรุปรายได้ประจำวันจากการขายหน้าร้าน | C33: 60000 | D33: =C33*7/107 -> 3925.2336 | N33: รายงานยอดขายประจำวัน
A34: 243992 | B34: ซื้อของ จาก ร้านน้องดาว ขายส่ง | G34: 45650 | N34: ใบสำคัญรับเงิน
B35: สรุปรายได้ประจำวันจากการขายหน้าร้าน | C35: 120000 | D35: =C35*7/107 -> 7850.4673 | N35: รายงานยอดขายประจำวัน
A36: 243993 | B36: ซื้อของ จาก Makro | F36: 13590 | L36: =F36*7/107 -> 889.06542 | N36: บิลสมบูรณ์
B37: ซื้อน้ำแข็ง | J37: 2000 | N37: บิลเงินสด+ใบรับรองแทนใบเสร็จรับเงิน
B38: สรุปรายได้ประจำวันจากการขายหน้าร้าน | C38: 150000 | D38: =C38*7/107 -> 9813.0841 | N38: รายงานยอดขายประจำวัน
A39: 243994 | B39: ซื้อของ จาก Big C | F39: 8340 | L39: =F39*7/107 -> 545.60748 | N39: บิลสมบูรณ์
B40: สรุปรายได้ประจำวันจากการขายหน้าร้าน | C40: 180000 | D40: =C40*7/107 -> 11775.701 | N40: รายงานยอดขายประจำวัน
A41: 243995 | B41: ซื้อของ จาก Lotus's | F41: 6070 | L41: =F41*7/107 -> 397.1028 | N41: บิลสมบูรณ์
...

Sheet template
A1: รายงานจดรับ-จ่าย : | C1: พฤษภาคม2569 | D1: เงินเดือน
A2: ชื่อสถานประกอบการ (ชื่อร้าน) : | D2: ค่าดูแลรถ | E2: 0
A3: เลขผู้เสียภาษีอากร : | D3: สถานะ : VAT
A5: ว/ด/ป | B5: รายการ | C5: จน เที่ยวน้ำมัน | D5: รายรับ | F5: รายจ่าย | J5: VAT ซื้อ | K5: เอกสาร
D6: รายรับ | E6: VAT ขาย | F6: ซื้อของ | G6: ค่าแรง | H6: เงินเดือน+ดูแลรถ | K6: บิลค่าใช้จ่าย
D39: =SUM(D7:D38) -> 0 | E39: =SUM(E7:E38) -> 0 | F39: =SUM(F7:F38) -> 0 | G39: =SUM(G7:G38) -> 0 | H39: =SUM(H7:H38) -> 0 | J39: =SUM(J7:J38) -> 0
A40: จ่ายพนักงานสิ้นเดือน (นิค) | B40: =H13+G14+G15+H16+H17 -> 0 | C40: ค่าเติมน้ำมัน ผ่านท่า | D40: =SUMIF(B7:B38, "*"&"น้ำมัน"&"*", F7:F38) -> 0
A41: รวมรายจ่าย | B41: =sum(F39:H39) -> 0 | C41: ค่าซ่อมรถ อื่นๆ | D41: =F39-D40 -> 0
A42: กำไรขั้นต้นในเดือน | B42: =J50-B41 -> 0
A45: ว/ด/ป | C45: คำนวณค่าตู้ | K45: ราคาตู้ | L45: จ่ายคนขับ | M45: รายรับ
B46: ตู้ตกหล่นจาก app | C46: เล็ก | D46: กลาง | E46: ใหญ่ | F46: รวมจำนวนตู้ | G46: เงินพิเศษ | H46: รวมที่ต้องจ่าย | I46: เบิกไปแล้ว | J46: รายรับรวม(หลังหัก 10%) | K46: เล็ก | L46: 100 | M46: 630
F47: =sum(B47:E47) -> 0 | H47: =F47*$L$46 -> 0 | J47: =0.9*(((B47+C47)*$M$46)+(D47*$M$48)+(E47*$M$49)) -> 0
A48: 244627 | F48: =sum(B48:E48) -> 0 | G48: 0 | H48: =F48*$L$46 -> 0 | J48: =0.9*(((B48+C48)*$M$46)+(D48*$M$48)+(E48*$M$49)) -> 0 | K48: กลาง | L48: 100 | M48: 680
A49: 20/5/2569 | F49: =sum(B49:E49) -> 0 | G49: 0 | H49: =F49*$L$46 -> 0 | J49: =0.9*(((B49+C49)*$M$46)+(D49*$M$48)+(E49*$M$49)) -> 0 | K49: ใหญ่ | L49: 100 | M49: 680
A50: 30/5/2569 | F50: =sum(B50:E50) -> 0 | H50: =F50*$L$46 -> 0 | J50: =0.9*(((B50+C50)*$M$46)+(D50*$M$48)+(E50*$M$49)) -> 0
G51: รวมเบิกไปแล้ว | I51: =SUM(I48:I50) -> 0 | L51: การคิดเงินพิเศษ
G52: ค้างจ่ายค่าเที่ยว | H52: =H50-I51 -> 0 | L52: 150 | M52: 1000
L53: 160 | M53: 2000
L54: 170 | M54: 3000
L55: 180 | M55: 4000
L56: 190 | M56: 5000
L57: 200 | M57: 6000
L58: 210 | M58: 7000
L59: 230 | M59: 9000

Sheet 39 506 Bonbon
A1: รายงานจดรับ-จ่าย : | C1: =template!$C$1 -> พฤษภาคม2569 | D1: เงินเดือน | E1: 10000 | G1: ตู้ | H1: 0931069789 | J1: ประกันสังคม
A2: ชื่อสถานประกอบการ (ชื่อร้าน) : | C2: บุญโลม ผุยเพ็ง | D2: ค่าดูแลรถ | E2: 2000
A3: เลขผู้เสียภาษีอากร : | C3: 3301700588011 | D3: สถานะ : VAT | G3: Reset | J3: ='ทะเบียน ประกัน'!C4 -> 74-5230 | K3: ='ทะเบียน ประกัน'!I4 -> 74-8395
A5: ว/ด/ป | B5: รายการ | C5: จน เที่ยวน้ำมัน | D5: รายรับ | F5: รายจ่าย | J5: VAT ซื้อ | K5: เอกสาร
D6: รายรับ | E6: VAT ขาย | F6: ซื้อของ | G6: ค่าแรง | H6: เงินเดือน+ดูแลรถ | K6: บิลค่าใช้จ่าย
A7: 244444 | B7: เติมน้ำมัน ผ่านท่า | C7: 34 | F7: 8100 | J7: =F7/C7 -> 238.23529 | K7: เต็ม
A8: 244566 | B8: เติมน้ำมัน ผ่านท่า | C8: 35 | F8: 8100 | J8: =F8/C8 -> 231.42857 | K8: เต็ม
A9: 244688 | B9: ติดฟิล์ม hi kool 60 รอบคัน ผ่านท่า | F9: 6520
A10: 13/5/2569 | B10: เติมน้ำมัน ผ่านท่า | C10: 28 | F10: =8100-940 -> 7160 | J10: =F10/C10 -> 255.71429
A11: 13/5/2569 | B11: ซ่อมกลอนประตู กระจก | F11: 2500
A12: 18/5/2569 | B12: เติมน้ำมัน ผ่านท่า | C12: 34 | F12: 8100 | J12: =F12/C12 -> 238.23529
A13: 23/5/2569 | B13: เติมน้ำมัน ผ่านท่า | C13: 27 | F13: 8600 | J13: =F13/C13 -> 318.51852 | K13: มาสมุทรปราการด้วย
A14: 30/5/2569 | B14: เติมน้ำมัน ผ่านท่า | C14: 36 | F14: =8600-300 -> 8300 | J14: =F14/C14 -> 230.55556
A24: =template!$A$48 -> 244627 | B24: เบิกค่าเที่ยว | G24: =I39 -> 5000
A25: =template!$A$49 -> 20/5/2569 | B25: เบิกค่าเที่ยว | G25: =I40 -> 0
A26: =template!$A$50 -> 30/5/2569 | B26: เบิกค่าเที่ยว | G26: =I41 -> 14700
A27: =template!$A$50 -> 30/5/2569 | B27: จ่ายเงินเดือน ดูแลรถ | H27: =C47+E2 -> 14000
A28: =template!$A$50 -> 30/5/2569 | B28: เงินพิเศษ อื่นๆ | G28: 0
A29: =template!$A$50 -> 30/5/2569 | B29: เงินพิเศษ | G29: =G41 -> 5000
A30: =template!$A$50 -> 30/5/2569 | B30: ประกันสังคม | H30: =C52 -> -875
D31: =SUM(D7:D30) -> 0 | E31: =SUM(E7:E30) -> 0 | F31: =SUM(F7:F30) -> 57380 | G31: =SUM(G7:G30) -> 24700 | H31: =SUM(H7:H30) -> 13125 | J31: =SUM(J7:J30) -> 1512.6875
A32: จ่ายพนักงานสิ้นเดือน | B32: =H27+G28+G29+H30 -> 18125 | C32: ค่าเติมน้ำมัน ผ่านท่า | D32: =SUMIF(B7:B30, "*"&"น้ำมัน"&"*", F7:F30) -> 48360
A33: รวมรายจ่าย | B33: =sum(F31:H31) -> 95205 | C33: ค่าซ่อมรถ อื่นๆ | D33: =F31-D32 -> 9020
A34: กำไรขั้นต้นในเดือน | B34: =J41-B33 -> 31227.9
A37: ว/ด/ป | C37: คำนวณค่าตู้ | K37: ราคาตู้ | L37: จ่ายคนขับ | M37: รายรับ
B38: ตู้ตกหล่นจาก app | C38: เล็ก | D38: กลาง | E38: ใหญ่ | F38: รวมจำนวนตู้ | G38: เงินพิเศษ | H38: รวมที่ต้องจ่าย | I38: เบิกไปแล้ว | J38: รายรับรวม(หลังหัก 10%) | K38: เล็ก | L38: 100 | M38: 630
A39: =template!$A$48 -> 244627 | C39: 52 | D39: 25 | F39: =sum(B39:E39) -> 77 | G39: 0 | H39: =F39*$L$38 -> 7700 | I39: 5000 | J39: =0.99*(((B39+C39)*$M$38)+(D39*$M$39)+(E39*$M$40)) -> 49262.4 | K39: กลาง | L39: 100 | M39: 680
A40: =template!$A$49 -> 20/5/2569 | F40: =sum(B40:E40) -> 0 | G40: 0 | H40: =F40*$L$38 -> 0 | I40: 0 | J40: =0.99*(((B40+C40)*$M$38)+(D40*$M$39)+(E40*$M$40)) -> 0 | K40: ใหญ่ | L40: 100 | M40: 680
A41: =template!$A$50 -> 30/5/2569 | B41: 2 | C41: 123 | D41: 72 | F41: =sum(B41:E41) -> 197 | G41: =IF(F41<150, 0, ((INT(F41/10)*10 - 140) / 10) * 1000) -> 5000 | H41: =F41*$L$38 -> 19700 | I41: 14700 | J41: =0.99*(((B41+C41)*$M$38)+(D41*$M$39)+(E41*$M$40)) -> 126432.9
G42: รวมเบิกไปแล้ว | I42: =SUM(I39:I41) -> 19700 | L42: การคิดเงินพิเศษ
G43: ค้างจ่ายค่าเที่ยว | H43: =H41-I42 -> 0 | L43: 150 | M43: 1000
L44: 160 | M44: 2000
B45: สรุปรายรับ จ่ายพนักงาน | C45: =C2 -> บุญโลม ผุยเพ็ง | L45: 170 | M45: 3000
B46: รายรับ | L46: 180 | M46: 4000
B47: เงินเดือน ดูแลรถ | C47: =IF(F$41>120, E$1, E$1-2000) +E2 -> 12000 | L47: 190 | M47: 5000
B48: ค่าเที่ยว | C48: =H41 -> 19700 | L48: 200 | M48: 6000
B49: เงินพิเศษ | C49: =G41 -> 5000 | L49: 210 | M49: 7000
L50: 220 | M50: 8000
B51: รายรับรวม | C51: =sum(C47:C50) -> 36700 | L51: 230 | M51: 9000
B52: หักประกันสังคม | C52: =-MIN(C51*5%, 875) -> -875
...

Sheet 47 507 จันทร์
A1: รายงานจดรับ-จ่าย : | C1: =template!$C$1 -> พฤษภาคม2569 | D1: เงินเดือน | E1: 10000
A2: ชื่อสถานประกอบการ (ชื่อร้าน) : | C2: ทองจันทร์ อ่อนคำ | D2: ค่าดูแลรถ | E2: 2000 | G2: 7291029065
A3: เลขผู้เสียภาษีอากร : | D3: สถานะ : VAT | I3: ='ทะเบียน ประกัน'!C5 -> 73-3382 | J3: ='ทะเบียน ประกัน'!I5 -> 73-7154
A5: ว/ด/ป | B5: รายการ | C5: จน เที่ยวน้ำมัน | D5: รายรับ | F5: รายจ่าย | J5: VAT ซื้อ | K5: เอกสาร
D6: รายรับ | E6: VAT ขาย | F6: ซื้อของ | G6: ค่าแรง | H6: เงินเดือน+ดูแลรถ | K6: บิลค่าใช้จ่าย
A7: 244354 | B7: ซ่อมแอร์สายกลางรั่ว ไฟคอยล์ | F7: 9735 | K7: ไม่เต็มถัง
A8: 244385 | B8: ผ่านท่า | F8: 100
A9: 244385 | B9: เติมน้ำมัน ผ่านท่า | C9: 34 | F9: 8600 | J9: =F9/C9 -> 252.94118 | K9: ไม่เต็มถัง
A10: 244413 | B10: ปะยาง | F10: 400
A11: 244474 | B11: ที่ปัดน้ำฝน | F11: 810 | K11: เต็ม
A12: 244505 | B12: เติมน้ำมัน ผ่านท่า | C12: 38 | F12: =8600-300 -> 8300 | J12: =F12/C12 -> 218.42105 | K12: เต็ม
A13: 244627 | B13: ไฟท่อกลม LED ผ่านท่า | F13: 688.5
A14: 244627 | B14: ครัชคอมแอร์ | F14: 3500
A15: 244658 | B15: เติมน้ำมัน ผ่านท่า | F15: 8300
A16: 244688 | B16: ติดฟิล์ม hi kool 80 รอบคัน บานหน้า 60 | F16: 6520
A17: 13/5/2569 | B17: มอไซด์ | F17: 180
A18: 15/5/2569 | B18: พักลมระผึ้ง | F18: 3050
A19: 15/5/2569 | B19: เปลี่ยนสายน้ำมัน ผ่านท่า | F19: 600
A20: 18/5/2569 | B20: เติมน้ำมัน ผ่านท่า | C20: 36 | F20: 8600 | J20: =F20/C20 -> 238.88889
A21: 23/5/2569 | B21: มินิวาล์ว ลูกยางมือเสือ นมบ | F21: 1699.55
A22: 23/5/2569 | B22: เติมน้ำมัน ผ่านท่า | C22: 38 | F22: 8500 | J22: =F22/C22 -> 223.68421
A23: 26/5/2568 | B23: ซ่อมพัดลม อัดจารบี ตั้งเบรค ผ่านท่า | F23: 1500
A24: 29/5/2569 | B24: เติมน้ำมัน ผ่านท่า | C24: 36 | F24: 8500 | J24: =F24/C24 -> 236.11111
A25: =template!$A$48 -> 244627 | B25: เบิกค่าเที่ยว | G25: =I40 -> 8000
A26: =template!$A$49 -> 20/5/2569 | B26: เบิกค่าเที่ยว | G26: =I41 -> 6200
A27: =template!$A$50 -> 30/5/2569 | B27: เบิกค่าเที่ยว | G27: =I42 -> 8900
A28: =template!$A$50 -> 30/5/2569 | B28: จ่ายเงินเดือน ดูแลรถ | H28: =C48+E2 -> 14000
A29: =template!$A$50 -> 30/5/2569 | B29: เงินพิเศษ อื่นๆ | G29: 0
A30: =template!$A$50 -> 30/5/2569 | B30: เงินพิเศษ | G30: =G42 -> 9000
A31: =template!$A$50 -> 30/5/2569 | B31: หักส่วนบุคคล | H31: =C53 -> -1323
D32: =SUM(D7:D31) -> 0 | E32: =SUM(E7:E31) -> 0 | F32: =SUM(F7:F31) -> 79583.05 | G32: =SUM(G7:G31) -> 32100 | H32: =SUM(H7:H31) -> 12677 | J32: =SUM(J7:J31) -> 1170.0464
A33: จ่ายพนักงานสิ้นเดือน | B33: =H28+G29+G30+H31 -> 21677 | C33: ค่าเติมน้ำมัน ผ่านท่า | D33: =SUMIF(B7:B31, "*"&"น้ำมัน"&"*", F7:F31) -> 51400
A34: รวมรายจ่าย | B34: =sum(F32:H32) -> 124360.05 | C34: ค่าซ่อมรถ อื่นๆ | D34: =F32-D33 -> 28183.05
A35: กำไรขั้นต้นในเดือน | B35: =J42-B34 -> 23179.65
A38: ว/ด/ป | C38: คำนวณค่าตู้ | K38: ราคาตู้ | L38: จ่ายคนขับ | M38: รายรับ
B39: ตู้ตกหล่นจาก app | C39: เล็ก | D39: กลาง | E39: ใหญ่ | F39: รวมจำนวนตู้ | G39: เงินพิเศษ | H39: รวมที่ต้องจ่าย | I39: เบิกไปแล้ว | J39: รายรับรวม(หลังหัก 10%) | K39: เล็ก | L39: 100 | M39: 630
A40: =template!$A$48 -> 244627 | C40: 59 | D40: 22 | F40: =sum(B40:E40) -> 81 | G40: 0 | H40: =F40*$L$39 -> 8100 | I40: 8000 | J40: =0.99*(((B40+C40)*$M$39)+(D40*$M$40)+(E40*$M$41)) -> 51608.7 | K40: กลาง | L40: 100 | M40: 680
A41: =template!$A$49 -> 20/5/2569 | C41: 100 | D41: 43 | F41: =sum(B41:E41) -> 143 | G41: 0 | H41: =F41*$L$39 -> 14300 | I41: 6200 | J41: =0.99*(((B41+C41)*$M$39)+(D41*$M$40)+(E41*$M$41)) -> 91317.6 | K41: ใหญ่ | L41: 100 | M41: 680
A42: =template!$A$50 -> 30/5/2569 | B42: 1 | C42: 160 | D42: 70 | F42: =sum(B42:E42) -> 231 | G42: =IF(F42<150, 0, ((INT(F42/10)*10 - 140) / 10) * 1000) -> 9000 | H42: =F42*$L$39 -> 23100 | I42: 8900 | J42: =0.99*(((B42+C42)*$M$39)+(D42*$M$40)+(E42*$M$41)) -> 147539.7
G43: รวมเบิกไปแล้ว | I43: =SUM(I40:I42) -> 23100 | L43: การคิดเงินพิเศษ
...

Sheet 48 508 นิค
A1: รายงานจดรับ-จ่าย : | C1: =template!$C$1 -> พฤษภาคม2569 | D1: เงินเดือน | E1: 12000 | G1: ประกันสังคม
A2: ชื่อสถานประกอบการ (ชื่อร้าน) : | C2: วงศกร กลิ่นบุญเกิด | D2: ค่าดูแลรถ | E2: 0
A3: เลขผู้เสียภาษีอากร : | C3: 1909800084592 | D3: สถานะ : VAT | I3: ='ทะเบียน ประกัน'!C6 -> 74-8394 | J3: ='ทะเบียน ประกัน'!I6 -> 73-3384
A5: ว/ด/ป | B5: รายการ | C5: จน เที่ยวน้ำมัน | D5: รายรับ | F5: รายจ่าย | J5: VAT ซื้อ | K5: เอกสาร
D6: รายรับ | E6: VAT ขาย | F6: ซื้อของ | G6: ค่าแรง | H6: เงินเดือน+ดูแลรถ | K6: บิลค่าใช้จ่าย
A7: 244413 | B7: เติมน้ำมัน ผ่านท่า | C7: 37 | F7: 10100 | J7: =F7/C7 -> 272.97297 | K7: 38(25,13)
A8: 244627 | B8: เติมน้ำมัน ผ่านท่า | C8: 38 | F8: 10100 | J8: =F8/C8 -> 265.78947 | K8: 36(26,10)
A9: 244658 | B9: วาล์วหม้อน้ำ น้ำยาหล่อเย็น | F9: 3531
A10: 244658 | B10: ปะเก็นปั้มน้ำ น้ำมันพาวเวอร์ ท่อยาง | F10: 695.45
A11: 13/5/2569 | B11: ค่าซ่อมเปลี่ยนวาล์ว ช่างเอ | F11: 1000
A12: 20/5/2569 | B12: เติมน้ำมัน ผ่านท่า | C12: 35 | F12: 10100 | J12: =F12/C12 -> 288.57143
A13: 26/5/2569 | B13: เติมน้ำมัน ผ่านท่า | C13: 30 | F13: 10100 | J13: =F13/C13 -> 336.66667 | K13: สมุทรปราการ
A25: =template!$A$48 -> 244627 | B25: เบิกค่าเที่ยว | G25: =I40 -> 3500
A26: =template!$A$49 -> 20/5/2569 | B26: เบิกค่าเที่ยว | G26: =I41 -> 0
A27: =template!$A$50 -> 30/5/2569 | B27: เบิกค่าเที่ยว | G27: =I42 -> 11500
A28: =template!$A$50 -> 30/5/2569 | B28: จ่ายเงินเดือน ดูแลรถ | H28: =E1 -> 12000
A29: =template!$A$50 -> 30/5/2569 | B29: เงินพิเศษ อื่นๆ | G29: 0
A30: =template!$A$50 -> 30/5/2569 | B30: เงินพิเศษ | G30: =G42 -> 1000
A31: =template!$A$50 -> 30/5/2569 | B31: หักประกันสังคม | H31: =C52 -> -875
D32: =SUM(D7:D31) -> 0 | E32: =SUM(E7:E31) -> 0 | F32: =SUM(F7:F31) -> 45626.45 | G32: =SUM(G7:G31) -> 16000 | H32: =SUM(H7:H31) -> 11125 | J32: =SUM(J7:J31) -> 1164.0005
A33: จ่ายพนักงานสิ้นเดือน (พี่จบ) | B33: =H28+G29+G30+H31 -> 12125 | C33: ค่าเติมน้ำมัน ผ่านท่า | D33: =SUMIF(B7:B31, "*"&"น้ำมัน"&"*", F7:F31) -> 41095.45
A34: รวมรายจ่าย | B34: =sum(F32:H32) -> 72751.45 | C34: ค่าซ่อมรถ อื่นๆ | D34: =F32-D33 -> 4531
A35: กำไรขั้นต้นในเดือน | B35: =J42-B34 -> 23130.05
A38: ว/ด/ป | C38: คำนวณค่าตู้ | K38: ราคาตู้ | L38: จ่ายคนขับ | M38: รายรับ
B39: ตู้ตกหล่นจาก app | C39: เล็ก | D39: กลาง | E39: ใหญ่ | F39: รวมจำนวนตู้ | G39: เงินพิเศษ | H39: รวมที่ต้องจ่าย | I39: เบิกไปแล้ว | J39: รายรับรวม(หลังหัก 10%) | K39: เล็ก | L39: 100 | M39: 630
A40: =template!$A$48 -> 244627 | C40: 31 | D40: 10 | F40: =sum(B40:E40) -> 41 | G40: 0 | H40: =F40*$L$39 -> 4100 | I40: 3500 | J40: =0.99*(((B40+C40)*$M$39)+(D40*$M$40)+(E40*$M$41)) -> 26066.7 | K40: กลาง | L40: 100 | M40: 680
A41: =template!$A$49 -> 20/5/2569 | F41: =sum(B41:E41) -> 0 | G41: 0 | H41: =F41*$L$39 -> 0 | I41: 0 | J41: =0.99*(((B41+C41)*$M$39)+(D41*$M$40)+(E41*$M$41)) -> 0 | K41: ใหญ่ | L41: 100 | M41: 680
A42: =template!$A$50 -> 30/5/2569 | C42: 103 | D42: 47 | F42: =sum(B42:E42) -> 150 | G42: =IF(F42<150, 0, ((INT(F42/10)*10 - 140) / 10) * 1000) -> 1000 | H42: =F42*$L$39 -> 15000 | I42: 11500 | J42: =0.99*(((B42+C42)*$M$39)+(D42*$M$40)+(E42*$M$41)) -> 95881.5
G43: รวมเบิกไปแล้ว | I43: =SUM(I40:I42) -> 15000 | L43: การคิดเงินพิเศษ
G44: ค้างจ่ายค่าเที่ยว | H44: =H42-I43 -> 0 | L44: 150 | M44: 1000
B45: สรุปรายรับ จ่ายพนักงาน | C45: =C2 -> วงศกร กลิ่นบุญเกิด | L45: 160 | M45: 2000
B46: รายรับ | L46: 170 | M46: 3000
B47: เงินเดือน | C47: =IF(F$42>120, E$1, E$1-2000) + E2 -> 12000 | F47: =D33/F42 -> 273.96967 | L47: 180 | M47: 4000
B48: ค่าเที่ยว | C48: =H42 -> 15000 | L48: 190 | M48: 5000
B49: เงินพิเศษ | C49: =G42 -> 1000 | L49: 200 | M49: 6000
F50: function resetExcelValues() { var sheet = SpreadsheetApp.getActiveSpreadsheet().getActiveSheet(); // ระบุช่องที่ต้องการล้างข้อมูล sheet.getRangeList(['B2', 'C4:C10', 'E2']).clearContent(); } | L50: 210 | M50: 7000
B51: รายรับรวม | C51: =sum(C47:C50) -> 28000 | L51: 220 | M51: 8000
B52: หักประกันสังคม | C52: =-MIN(C51*5%, 875) -> -875 | L52: 230 | M52: 9000
B53: เบิกค่าเที่ยวไปแล้ววันที่ 10 | C53: =-I40 -> -3500
B54: เบิกค่าเที่ยวไปแล้ววันที่ 20 | C54: =-I41 -> 0
...

Sheet 501 เต่า
A1: รายงานจดรับ-จ่าย : | C1: =template!$C$1 -> พฤษภาคม2569 | D1: เงินเดือน | E1: 12000 | G1: 0625198007 | I1: ประกันสังคม
A2: ชื่อสถานประกอบการ (ชื่อร้าน) : | C2: สายัน หงษ์สันเทียะ | D2: ค่าดูแลรถ | E2: 0
A3: เลขผู้เสียภาษีอากร : | C3: 5300800103597 | D3: สถานะ : VAT | I3: ='ทะเบียน ประกัน'!C7 -> 74-8874 | J3: ='ทะเบียน ประกัน'!I7 -> 74-8875
A5: ว/ด/ป | B5: รายการ | C5: จน เที่ยวน้ำมัน | D5: รายรับ | F5: รายจ่าย | J5: VAT ซื้อ | K5: เอกสาร
D6: รายรับ | E6: VAT ขาย | F6: ซื้อของ | G6: ค่าแรง | H6: เงินเดือน+ดูแลรถ | K6: บิลค่าใช้จ่าย
A7: 244385 | B7: เติมน้ำมัน ผ่านท่า | C7: 48 | F7: 13000 | J7: =F7/C7 -> 270.83333 | K7: 58(45,13)
A8: 244413 | B8: เช็คลมยาง | F8: 600
A9: 244566 | B9: เติมน้ำมัน ผ่านท่า | C9: 49 | F9: 13000 | J9: =F9/C9 -> 265.30612 | K9: 48(35,13)
A10: 15/5/2569 | B10: ปะยาง | F10: 800
A11: 16/5/2569 | B11: เติมน้ำมัน ผ่านท่า | C11: 42 | F11: 13000 | J11: =F11/C11 -> 309.52381 | K11: 42(27,15)
A12: 23/5/2569 | B12: เติมน้ำมัน ผ่านท่า | C12: 48 | F12: 13000 | J12: =F12/C12 -> 270.83333
A13: 30/5/2569 | B13: เติมน้ำมัน ผ่านท่า | F13: 13000 | J13: =F13/C13 -> #DIV/0!
J14: =F14/C14 -> #DIV/0!
J15: =F15/C15 -> #DIV/0!
A22: =template!$A$50 -> 30/5/2569 | B22: หักเงินยืมงวดที่ 2 (ต้น 12000) | D22: 2000
A23: =template!$A$48 -> 244627 | B23: เบิกค่าเที่ยว | G23: =I39 -> 7800
A24: =template!$A$49 -> 20/5/2569 | B24: เบิกค่าเที่ยว | G24: =I40 -> 5000
A25: =template!$A$50 -> 30/5/2569 | B25: เบิกค่าเที่ยว | G25: =I41 -> 7000
A26: =template!$A$50 -> 30/5/2569 | B26: หักค่าผ่อนกระบะ | D26: 6000
A27: =template!$A$50 -> 30/5/2569 | B27: จ่ายเงินเดือน ดูแลรถ | H27: =E1 -> 12000
A28: =template!$A$50 -> 30/5/2569 | B28: เงินพิเศษ อื่นๆ (หักค่ายืมเงิน 2000) | D28: 2000
A29: =template!$A$50 -> 30/5/2569 | B29: เงินพิเศษ | G29: =G41 -> 7000
A30: =template!$A$50 -> 30/5/2569 | B30: ประกันสังคม | H30: =C53 -> -875
D31: =SUM(D7:D30) -> 10000 | E31: =SUM(E7:E30) -> 0 | F31: =SUM(F7:F30) -> 66400 | G31: =SUM(G7:G30) -> 26800 | H31: =SUM(H7:H30) -> 11125 | J31: =SUM(J7:J30) -> #DIV/0!
A32: จ่ายพนักงานสิ้นเดือน | B32: =H27+G28+G29+H30-D26 -> 12125 | C32: ค่าเติมน้ำมัน ผ่านท่า | D32: =SUMIF(B7:B30, "*"&"น้ำมัน"&"*", F7:F30) -> 65000
A33: รวมรายจ่าย | B33: =sum(F31:H31) -> 104325 | C33: ค่าซ่อมรถ อื่นๆ | D33: =F31-D32 -> 1400
A34: กำไรขั้นต้นในเดือน | B34: =J41-B33 -> 31017.9
A37: ว/ด/ป | C37: คำนวณค่าตู้ | K37: ราคาตู้ | L37: จ่ายคนขับ | M37: รายรับ
B38: ตู้ตกหล่นจาก app | C38: เล็ก | D38: กลาง | E38: ใหญ่ | F38: รวมจำนวนตู้ | G38: เงินพิเศษ | H38: รวมที่ต้องจ่าย | I38: เบิกไปแล้ว | J38: รายรับรวม | K38: เล็ก | L38: 100 | M38: 630
A39: =template!$A$48 -> 244627 | B39: 1 | C39: 53 | D39: 24 | F39: =sum(B39:E39) -> 78 | G39: 0 | H39: =F39*$L$38 -> 7800 | I39: 7800 | J39: =(((B39+C39)*$M$38)+(D39*$M$39)+(E39*$M$40))*0.99 -> 49836.6 | K39: กลาง | L39: 100 | M39: 680
A40: =template!$A$49 -> 20/5/2569 | B40: 1 | C40: 90 | D40: 40 | F40: =sum(B40:E40) -> 131 | G40: 0 | H40: =F40*$L$38 -> 13100 | I40: 5000 | J40: =(((B40+C40)*$M$38)+(D40*$M$39)+(E40*$M$40))*0.99 -> 83684.7 | K40: ใหญ่ | L40: 100 | M40: 680
A41: =template!$A$50 -> 30/5/2569 | B41: 2 | C41: 147 | D41: 63 | F41: =sum(B41:E41) -> 212 | G41: =IF(F41<150, 0, ((INT(F41/10)*10 - 140) / 10) * 1000) -> 7000 | H41: =(F41*$L$39) -> 21200 | I41: 7000 | J41: =(((B41+C41)*$M$38)+(D41*$M$39)+(E41*$M$40))*0.99 -> 135342.9
G42: รวมเบิกไปแล้ว | I42: =SUM(I39:I41) -> 19800 | L42: การคิดเงินพิเศษ
G43: ค้างจ่ายค่าเที่ยว | H43: =H41-I42 -> 1400 | L43: 150 | M43: 1000
L44: 160 | M44: 2000
L45: 170 | M45: 3000
B46: สรุปรายรับ จ่ายพนักงาน | C46: =C2 -> สายัน หงษ์สันเทียะ | L46: 180 | M46: 4000
B47: รายรับ | F47: =D32/F41 -> 306.60377 | L47: 190 | M47: 5000
B48: เงินเดือน | C48: =IF(F$41>120, E$1, E$1-2000) -> 12000 | L48: 200 | M48: 6000
B49: ค่าเที่ยว | C49: =H41 -> 21200 | L49: 210 | M49: 7000
...

Sheet 502 ป๋า
A1: รายงานจดรับ-จ่าย : | C1: =template!$C$1 -> พฤษภาคม2569 | D1: เงินเดือน | E1: 13000 | G1: ประกันสังคม
A2: ชื่อสถานประกอบการ (ชื่อร้าน) : | C2: นพดล แคนลา | D2: ค่าดูแลรถ | E2: 0
A3: เลขผู้เสียภาษีอากร : | C3: 3100501751398 | D3: สถานะ : VAT | I3: ='ทะเบียน ประกัน'!C8 -> 74-9438 | J3: ='ทะเบียน ประกัน'!I8 -> 74-9697
A5: ว/ด/ป | B5: รายการ | C5: จน เที่ยวน้ำมัน | D5: รายรับ | F5: รายจ่าย | J5: VAT ซื้อ | K5: เอกสาร
D6: รายรับ | E6: VAT ขาย | F6: ซื้อของ | G6: ค่าแรง | H6: เงินเดือน+ดูแลรถ | K6: บิลค่าใช้จ่าย
A7: 244354 | B7: เติมน้ำมัน ผ่านท่า | C7: 54 | F7: 12100 | J7: =F7/C7 -> 224.07407
A8: 244505 | B8: เติมน้ำมัน ผ่านท่า | C8: 51 | F8: 12100 | J8: =F8/C8 -> 237.2549 | K8: 51(34,17)
A9: 244688 | B9: เติมน้ำมัน ผ่านท่า | C9: 49 | F9: 12100 | J9: =F9/C9 -> 246.93878 | K9: 44(38,46)
A10: 13/5/2569 | B10: เช็คลม ย้ำน็อต | F10: 260
A11: 15/5/2569 | B11: ยางกะละมังตื้น 8นิ้วx4 สปริงดึงหม้อลมสั้นx3 | F11: 770.4
A12: 19/5/2569 | B12: เติมน้ำมัน ผ่านท่า | C12: 49 | F12: 12100 | J12: =F12/C12 -> 246.93878 | K12: 60(41,19)
A13: 24/5/2569 | B13: เติมน้ำมัน ผ่านท่า | C13: 48 | F13: 12100
A14: 30/5/2569 | B14: ทำราวข้างหาง อัดจารบีหัวหาง ตั้งเบรคตัวแม่ หาง ช่างเอ | F14: 1250
A24: =template!$A$48 -> 244627 | B24: เบิกค่าเที่ยว | G24: =I40 -> 8900
A25: =template!$A$49 -> 20/5/2569 | B25: เบิกค่าเที่ยว | G25: =I41 -> 8300
A26: =template!$A$50 -> 30/5/2569 | B26: เบิกค่าเที่ยว | G26: =I42 -> 8900
A27: =template!$A$50 -> 30/5/2569 | B27: หักเงินยืมงวดที่ 6 (ต้น 14000) | D27: 2000
A28: =template!$A$50 -> 30/5/2569 | B28: จ่ายเงินเดือน ดูแลรถ | H28: =E1 -> 13000
A29: =template!$A$50 -> 30/5/2569 | B29: เงินพิเศษ อื่นๆ | G29: 0
A30: =template!$A$50 -> 30/5/2569 | B30: เงินพิเศษ | G30: =G42 -> 12000
A31: =template!$A$50 -> 30/5/2569 | B31: ประกันสังคม | H31: =C53 -> -875
D32: =SUM(D7:D31) -> 2000 | E32: =SUM(E7:E31) -> 0 | F32: =SUM(F7:F31) -> 62780.4 | G32: =SUM(G7:G31) -> 38100 | H32: =SUM(H7:H31) -> 12125 | J32: =SUM(J7:J31) -> 955.20653
A33: จ่ายพนักงานสิ้นเดือน | B33: =H28+G29+G30+H31-D27 -> 22125 | C33: ค่าเติมน้ำมัน ผ่านท่า | D33: =SUMIF(B7:B31, "*"&"น้ำมัน"&"*", F7:F31) -> 60500
A34: รวมรายจ่าย | B34: =sum(F32:H32) -> 113005.4 | C34: ค่าซ่อมรถ อื่นๆ | D34: =F32-D33 -> 2280.4
A35: กำไรขั้นต้นในเดือน | B35: =J42-B34 -> 53938.3
A38: ว/ด/ป | C38: คำนวณค่าตู้ | K38: ราคาตู้ | L38: จ่ายคนขับ | M38: รายรับ
B39: ตู้ตกหล่นจาก app | C39: เล็ก | D39: กลาง | E39: ใหญ่ | F39: รวมจำนวนตู้ | G39: เงินพิเศษ | H39: รวมที่ต้องจ่าย | I39: เบิกไปแล้ว | J39: รายรับรวม | K39: เล็ก | L39: 100 | M39: 630
A40: =template!$A$48 -> 244627 | C40: 63 | D40: 26 | F40: =sum(B40:E40) -> 89 | G40: 0 | H40: =F40*$L$39 -> 8900 | I40: 8900 | J40: =(((B40+C40)*$M$39)+(D40*$M$40)+(E40*$M$41))*0.99 -> 56796.3 | K40: กลาง | L40: 100 | M40: 680
A41: =template!$A$49 -> 20/5/2569 | C41: =C40+62 -> 125 | D41: =D40+21 -> 47 | F41: =sum(B41:E41) -> 172 | G41: 0 | H41: =F41*$L$39 -> 17200 | I41: 8300 | J41: =(((B41+C41)*$M$39)+(D41*$M$40)+(E41*$M$41))*0.99 -> 109602.9 | K41: ใหญ่ | L41: 100 | M41: 680
A42: =template!$A$50 -> 30/5/2569 | B42: -1 | C42: 178 | D42: 84 | F42: =sum(B42:E42) -> 261 | G42: =IF(F42<150, 0, ((INT(F42/10)*10 - 140) / 10) * 1000) -> 12000 | H42: =(F42*$L$39) -> 26100 | I42: 8900 | J42: =(((B42+C42)*$M$39)+(D42*$M$40)+(E42*$M$41))*0.99 -> 166943.7
G43: รวมเบิกไปแล้ว | I43: =SUM(I40:I42) -> 26100 | L43: การคิดเงินพิเศษ
G44: ค้างจ่ายค่าเที่ยว | H44: =H42-I43 -> 0 | L44: 150 | M44: 1000
L45: 160 | M45: 2000
B46: สรุปรายรับ จ่ายพนักงาน | C46: =C2 -> นพดล แคนลา | L46: 170 | M46: 3000
B47: รายรับ | L47: 180 | M47: 4000
B48: เงินเดือน | C48: =IF(F$42>120, E$1, E$1-2000) +E2 -> 13000 | L48: 190 | M48: 5000
B49: ค่าเที่ยว | C49: =H42 -> 26100 | L49: 200 | M49: 6000
B50: เงินพิเศษ | C50: =G42 -> 12000 | L50: 210 | M50: 7000
L51: 220 | M51: 8000
B52: รายรับรวม | C52: =sum(C48:C51) -> 51100 | L52: 230 | M52: 9000
...

Sheet 503 ฟัก
A1: รายงานจดรับ-จ่าย : | C1: =template!$C$1 -> พฤษภาคม2569 | D1: เงินเดือน | E1: 10000
A2: ชื่อสถานประกอบการ (ชื่อร้าน) : | C2: วินัย เหวขุนทด | D2: ค่าดูแลรถ | E2: 0 | G2: ธกส | H2: 020048915219
A3: เลขผู้เสียภาษีอากร : | D3: สถานะ : VAT | I3: ='ทะเบียน ประกัน'!C9 -> 74-9437 | J3: ='ทะเบียน ประกัน'!I9 -> 74-7023
A5: ว/ด/ป | B5: รายการ | C5: จน เที่ยวน้ำมัน | D5: รายรับ | F5: รายจ่าย | J5: VAT ซื้อ | K5: เอกสาร
D6: รายรับ | E6: VAT ขาย | F6: ซื้อของ | G6: ค่าแรง | H6: เงินเดือน+ดูแลรถ | K6: บิลค่าใช้จ่าย
A7: 244354 | B7: เติมน้ำมัน ผ่านท่า | F7: 8100
A8: 244474 | B8: เติมน้ำมัน ผ่านท่า | C8: 27 | F8: =8000-1530 -> 6470 | J8: =F8/C8 -> 239.62963 | K8: 27(21,6)
A9: 244627 | B9: เติมน้ำมัน ผ่านท่า | C9: 27 | F9: =8000-1300 -> 6700 | J9: =F9/C9 -> 248.14815 | K9: 27(21,6)
A10: 244658 | B10: เปลี่ยนยาง สลับยาง ผ่านท่า | F10: 820
A11: 16/5/2569 | B11: เติมน้ำมัน ผ่านท่า | C11: 27 | F11: 6470 | J11: =F11/C11 -> 239.62963 | K11: 27(19,8)
A12: 22/5/2569 | B12: เติมน้ำมัน ผ่านท่า | F12: =8100-1300 -> 6800
A13: 22/5/2569 | B13: ค่าทางด่วน | F13: 210
A14: 30/5/2569 | B14: เติมน้ำมัน ผ่านท่า | F14: 6900
A26: 17/5/2569 | B26: ผ่อนรถ งวด8 | F26: 20271
A27: =template!$A$48 -> 244627 | B27: เบิกค่าเที่ยว | G27: =I43 -> 4600 | K27: สุริยะ วิ่งได้ 15 เที่ยว=2000 (โกงน้ำมัน) เอ็ม 13 เที่ยว = 1950
A28: =template!$A$49 -> 20/5/2569 | B28: เบิกค่าเที่ยว | G28: =I44 -> 4500
A29: =template!$A$50 -> 30/5/2569 | B29: เบิกค่าเที่ยว | G29: =I45 -> 5100
A30: =template!$A$50 -> 30/5/2569 | B30: หักเงินยืมเดือนละ 4000 งวด1 (ต้น 30000) | D30: 4000
A31: =template!$A$50 -> 30/5/2569 | B31: จ่ายเงินเดือน ดูแลรถ | H31: =E1 -> 10000
A32: =template!$A$50 -> 30/5/2569 | B32: เบิกเงินค่าเที่ยว
A33: =template!$A$50 -> 30/5/2569 | B33: เงินพิเศษ | G33: =G45 -> 0
A34: =template!$A$50 -> 30/5/2569 | B34: หักส่วนบุคคล | H34: =C55 -> -726
D35: =SUM(D7:D34) -> 4000 | E35: =SUM(E7:E34) -> 0 | F35: =SUM(F7:F34) -> 62741 | G35: =SUM(G7:G34) -> 14200 | H35: =SUM(H7:H34) -> 9274 | J35: =SUM(J8:J34) -> 727.40741
A36: จ่ายพนักงานสิ้นเดือน | B36: =H31+G32+G33+H34+H30 -> 9274 | C36: ค่าเติมน้ำมัน ผ่านท่า | D36: =SUMIF(B8:B34, "*"&"น้ำมัน"&"*", F8:F34) -> 33340
A37: รวมรายจ่าย | B37: =sum(F35:H35) -> 86215 | C37: ค่าซ่อมรถ อื่นๆ | D37: =F35-D36 -> 29401
A38: กำไรขั้นต้นในเดือน | B38: =J45-B37 -> 4033.4
A41: ว/ด/ป | C41: คำนวณค่าตู้ | K41: ราคาตู้ | L41: จ่ายคนขับ | M41: รายรับ
B42: ตู้ตกหล่นจาก app | C42: เล็ก | D42: กลาง | E42: ใหญ่ | F42: รวมจำนวนตู้ | G42: เงินพิเศษ | H42: รวมที่ต้องจ่าย | I42: เบิกไปแล้ว | J42: รายรับรวม | K42: เล็ก | L42: 100 | M42: 630
A43: =template!$A$48 -> 244627 | B43: 1 | C43: 34 | D43: 11 | F43: =sum(B43:E43) -> 46 | G43: 0 | H43: =F43*$L$42 -> 4600 | I43: 4600 | J43: =(((B43+C43)*$M$42)+(D43*$M$43)+(E43*$M$44))*0.99 -> 29234.7 | K43: กลาง | L43: 100 | M43: 680
A44: =template!$A$49 -> 20/5/2569 | B44: 1 | C44: 70 | D44: 21 | F44: =sum(B44:E44) -> 92 | G44: 0 | H44: =F44*$L$42 -> 9200 | I44: 4500 | J44: =(((B44+C44)*$M$42)+(D44*$M$43)+(E44*$M$44))*0.99 -> 58419.9 | K44: ใหญ่ | L44: 100 | M44: 680
A45: =template!$A$50 -> 30/5/2569 | B45: 4 | C45: 104 | D45: 34 | F45: =sum(B45:E45) -> 142 | G45: =IF(F45<150, 0, ((INT(F45/10)*10 - 140) / 10) * 1000) -> 0 | H45: =(F45*$L$43) -> 14200 | I45: 5100 | J45: =(((B45+C45)*$M$42)+(D45*$M$43)+(E45*$M$44))*0.99 -> 90248.4
G46: รวมเบิกไปแล้ว | I46: =SUM(I43:I45) -> 14200 | L46: การคิดเงินพิเศษ
G47: ค้างจ่ายค่าเที่ยว | H47: =H45-I46 -> 0 | L47: 150 | M47: 1000
B48: สรุปรายรับ จ่ายพนักงาน | C48: =C2 -> วินัย เหวขุนทด | L48: 160 | M48: 2000
B49: รายรับ | L49: 170 | M49: 3000
B50: เงินเดือน | C50: =IF(F$45>120, E$1, E$1-2000) +E2 -> 10000 | L50: 180 | M50: 4000
B51: ค่าเที่ยว | C51: =H45 -> 14200 | L51: 190 | M51: 5000
B52: เงินพิเศษ | C52: =G45 -> 0 | L52: 200 | M52: 6000
L53: 210 | M53: 7000
B54: รายรับรวม | C54: =sum(C50:C52) -> 24200 | L54: 220 | M54: 8000
...

Sheet 504 ประจบ
A1: รายงานจดรับ-จ่าย : | C1: =template!$C$1 -> พฤษภาคม2569 | D1: เงินเดือน | E1: 0 | G1: ประจบ | H1: 0844868353
A2: ชื่อสถานประกอบการ (ชื่อร้าน) : | C2: ประจบ กาชัย | D2: ค่าดูแลรถ | E2: 0
A3: เลขผู้เสียภาษีอากร : | C3: 3640500264014 | D3: สถานะ : VAT | I3: ='ทะเบียน ประกัน'!C10 -> 75-0287 สป | J3: ='ทะเบียน ประกัน'!I10 -> 75-0288 สป
A5: ว/ด/ป | B5: รายการ | C5: จน เที่ยวน้ำมัน | D5: รายรับ | F5: รายจ่าย | J5: VAT ซื้อ | K5: เอกสาร
D6: รายรับ | E6: VAT ขาย | F6: ซื้อของ | G6: ค่าแรง | H6: เงินเดือน+ดูแลรถ | K6: บิลค่าใช้จ่าย
A7: 244354 | B7: ซ่อมแอร์สายกลางรั่ว โอริง | F7: 7800 | J7: =F7/C7 -> #DIV/0!
A8: 244627 | B8: ค่ามอเตอร์ไซด์ ผ่านท่า | F8: 200
A9: 21/5/2569 | B9: ปะยาง | F9: 450
A10: 22/5/2569 | B10: เติมน้ำมัน ผ่านท่า | F10: 12000
A11: 30/5/2569 | B11: เติมน้ำมัน ผ่านท่า | C11: 47 | F11: =12000-990 -> 11010 | J11: =F11/C11 -> 234.25532
A24: 31/5/2569 | B24: จ่ายเงินค่ารับจ๊อปน้าเป็ด 9 เที่ยว | F24: =150*9 -> 1350
A25: 31/5/2569 | B25: จ่ายเงินค่ารับจ๊อปโรจน์ 65 เที่ยว | F25: =150*65 -> 9750
A26: 17/5/2569 | B26: ผ่อนรถ งวด6 | F26: 20271
A27: 17/5/2569 | B27: ผ่อนหาง งวด6 | F27: 3686
A28: =template!$A$48 -> 244627 | B28: เบิกค่าเที่ยว | G28: =I43
A29: =template!$A$49 -> 20/5/2569 | B29: เบิกค่าเที่ยว | G29: =I44
A30: =template!$A$50 -> 30/5/2569 | B30: เบิกค่าเที่ยว | G30: =I45
A31: =template!$A$50 -> 30/5/2569 | B31: จ่ายเงินเดือน ดูแลรถ | H31: =E1+E2 -> 0
A32: =template!$A$50 -> 30/5/2569 | B32: เงินพิเศษ อื่นๆ (สงกราน) | G32: 0
A33: =template!$A$50 -> 30/5/2569 | B33: เงินพิเศษ | G33: =G45 -> 0
A34: =template!$A$50 -> 30/5/2569 | B34: หักส่วนบุคคล | H34: =C55 -> -171
D35: =SUM(D8:D34) -> 0 | E35: =SUM(E8:E34) -> 0 | F35: =SUM(F7:F34) -> 66517 | G35: =SUM(G7:G34) -> 0 | H35: =SUM(H7:H34) -> -171 | J35: =SUM(J8:J34) -> 234.25532
A36: จ่ายพนักงานสิ้นเดือน | B36: =C58 -> 5529 | C36: ค่าเติมน้ำมัน ผ่านท่า | D36: =SUMIF(B8:B34, "*"&"น้ำมัน"&"*", F8:F34) -> 23010
A37: รวมรายจ่าย | B37: =sum(F35:H35) -> 66346 | C37: ค่าซ่อมรถ อื่นๆ | D37: =F35-D36 -> 43507
A38: กำไรขั้นต้นในเดือน | B38: =J45-B37 -> -17430.1
A41: ว/ด/ป | C41: คำนวณค่าตู้ | K41: ราคาตู้ | L41: จ่ายคนขับ | M41: รายรับ
B42: ตู้ตกหล่นจาก app | C42: เล็ก | D42: กลาง | E42: ใหญ่ | F42: รวมจำนวนตู้ | G42: เงินพิเศษ | H42: รวมที่ต้องจ่าย | I42: เบิกไปแล้ว | J42: รายรับรวม | K42: เล็ก | L42: 100 | M42: 630
A43: =template!$A$48 -> 244627 | F43: =sum(B43:E43) -> 0 | G43: 0 | H43: =F43*$L$42 -> 0 | J43: =(((B43+C43)*$M$42)+(D43*$M$43)+(E43*$M$44))*0.99 -> 0 | K43: กลาง | L43: 100 | M43: 680
A44: =template!$A$49 -> 20/5/2569 | F44: =sum(B44:E44) -> 0 | G44: 0 | H44: =F44*$L$42 -> 0 | J44: =(((B44+C44)*$M$42)+(D44*$M$43)+(E44*$M$44))*0.99 -> 0 | K44: ใหญ่ | L44: 100 | M44: 680
A45: =template!$A$50 -> 30/5/2569 | B45: 12 | C45: 47 | D45: 18 | F45: =sum(B45:E45) -> 77 | G45: =IF(F45<150, 0, ((INT(F45/10)*10 - 140) / 10) * 1000) -> 0 | H45: =(F45*$L$43) -> 7700 | J45: =(((B45+C45)*$M$42)+(D45*$M$43)+(E45*$M$44))*0.99 -> 48915.9
G46: รวมเบิกไปแล้ว | I46: =SUM(I43:I45) -> 0 | L46: การคิดเงินพิเศษ
G47: ค้างจ่ายค่าเที่ยว | H47: =H45-I46 -> 7700 | L47: 150 | M47: 1000
B48: สรุปรายรับ จ่ายพนักงาน | C48: =C2 -> ประจบ กาชัย | L48: 160 | M48: 2000
B49: รายรับ | L49: 170 | M49: 3000
B50: เงินเดือน | C50: =IF(F$45>120, E$1, E$1-2000) +E2 -> -2000 | L50: 180 | M50: 4000
B51: ค่าเที่ยว | C51: =H45 -> 7700 | L51: 190 | M51: 5000
B52: เงินพิเศษ | C52: =G45 -> 0 | L52: 200 | M52: 6000
L53: 210 | M53: 7000
B54: รายรับรวม | C54: =sum(C50:C53) -> 5700 | L54: 220 | M54: 8000
B55: หักส่วนบุคคล 3% | C55: =-C54*3% -> -171 | L55: 230 | M55: 9000
...

Sheet 505 เสริม เอ็ม บุญมี
A1: รายงานจดรับ-จ่าย : | C1: =template!$C$1 -> พฤษภาคม2569 | D1: เงินเดือน | E1: 10000 | H1: 0935427955
A2: ชื่อสถานประกอบการ (ชื่อร้าน) : | C2: บุญมี ศรีสุระ | D2: ค่าดูแลรถ | E2: 0 | G2: Kbank | H2: 1633291035
A3: เลขผู้เสียภาษีอากร : | C3: 3400600329942 | D3: สถานะ : VAT | I3: ='ทะเบียน ประกัน'!C11 -> 75-0286 สป | J3: ='ทะเบียน ประกัน'!I11 -> 75-0289 สป
A5: ว/ด/ป | B5: รายการ | C5: จน เที่ยวน้ำมัน | D5: รายรับ | F5: รายจ่าย | J5: VAT ซื้อ | K5: เอกสาร
D6: รายรับ | E6: VAT ขาย | F6: ซื้อของ | G6: ค่าแรง | H6: เงินเดือน+ดูแลรถ | K6: บิลค่าใช้จ่าย
A7: 244354 | B7: เติมน้ำมัน ผ่านท่า | C7: 29 | F7: 8100 | J7: =F7/C7 -> 279.31034
A8: 244474 | B8: เติมน้ำมัน ผ่านท่า | C8: 39 | F8: 10100 | J8: =F8/C8 -> 258.97436 | K8: 32(24,8)
A9: 244627 | B9: เติมน้ำมัน ผ่านท่า | C9: 35 | F9: 10100 | J9: =F9/C9 -> 288.57143 | K9: 35(31,4)
A10: 244688 | B10: ปะยาง | F10: 600
A11: 15/5/2569 | B11: เติมน้ำมัน ผ่านท่า | C11: 40 | F11: 10100 | J11: =F11/C11 -> 252.5 | K11: 40(29,11)
A12: 20/5/2569 | B12: เติมน้ำมัน ผ่านท่า | F12: 10100
A13: 26/5/2569 | B13: เติมน้ำมัน ผ่านท่า | F13: 10100
A14: 29/5/2569 | B14: ปั้มครัชล่างเบอร์ 505 หลอดไฟหน้าเบอร์ 506 หลอดไฟหน้าเบอร์ 501 | F14: 2942.5
A15: 30/5/2569 | B15: กรองอากาศ มอเตอร์ไซ ช่างเอ | F15: 1280
A26: 17/5/2569 | B26: ผ่อนรถ งวด6 | F26: 20271
A27: 17/5/2569 | B27: ผ่อนหาง งวด6 | F27: 3686
A28: =template!$A$48 -> 244627 | B28: เบิกค่าเที่ยว | F28: 0 | G28: =I43 -> 7100
A29: =template!$A$49 -> 20/5/2569 | B29: เบิกค่าเที่ยว | G29: =I44 -> 7300
A30: =template!$A$50 -> 30/5/2569 | B30: เบิกค่าเที่ยว | G30: =I45 -> 8300
A31: =template!$A$50 -> 30/5/2569 | B31: จ่ายเงินเดือน ดูแลรถ | H31: =E1 -> 10000
A32: =template!$A$50 -> 30/5/2569
A33: =template!$A$50 -> 30/5/2569 | B33: เงินพิเศษ | G33: =G45 -> 8000
A34: =template!$A$50 -> 30/5/2569 | B34: หักส่วนบุคคล | H34: =C55 -> -1221
D35: =SUM(D8:D34) -> 0 | E35: =SUM(E8:E34) -> 0 | F35: =SUM(F7:F34) -> 87379.5 | G35: =SUM(G7:G34) -> 30700 | H35: =SUM(H7:H34) -> 8779 | J35: =SUM(J8:J34) -> 800.04579
A36: จ่ายพนักงานสิ้นเดือน | B36: =C58 -> 25079 | C36: ค่าเติมน้ำมัน ผ่านท่า | D36: =SUMIF(B8:B34, "*"&"น้ำมัน"&"*", F8:F34) -> 50500
A37: รวมรายจ่าย | B37: =sum(F35:H35) -> 126858.5 | C37: ค่าซ่อมรถ อื่นๆ | D37: =F35-D36 -> 36879.5
A38: กำไรขั้นต้นในเดือน | B38: =J45-B37 -> 17394.4
A41: ว/ด/ป | C41: คำนวณค่าตู้ | K41: ราคาตู้ | L41: จ่ายคนขับ | M41: รายรับ
B42: ตู้ตกหล่นจาก app | C42: เล็ก | D42: กลาง | E42: ใหญ่ | F42: รวมจำนวนตู้ | G42: เงินพิเศษ | H42: รวมที่ต้องจ่าย | I42: เบิกไปแล้ว | J42: รายรับรวม | K42: เล็ก | L42: 100 | M42: 630
A43: =template!$A$48 -> 244627 | B43: 4 | C43: 55 | D43: 12 | F43: =sum(B43:E43) -> 71 | G43: 0 | H43: =F43*$L$42 -> 7100 | I43: 7100 | J43: =(((B43+C43)*$M$42)+(D43*$M$43)+(E43*$M$44))*0.99 -> 44876.7 | K43: กลาง | L43: 100 | M43: 680
A44: =template!$A$49 -> 20/5/2569 | B44: 4 | C44: 107 | D44: 33 | F44: =sum(B44:E44) -> 144 | G44: 0 | H44: =F44*$L$42 -> 14400 | I44: 7300 | J44: =(((B44+C44)*$M$42)+(D44*$M$43)+(E44*$M$44))*0.99 -> 91446.3 | K44: ใหญ่ | L44: 100 | M44: 680
A45: =template!$A$50 -> 30/5/2569 | B45: 12 | C45: 161 | D45: 54 | F45: =sum(B45:E45) -> 227 | G45: =IF(F45<150, 0, ((INT(F45/10)*10 - 140) / 10) * 1000) -> 8000 | H45: =F45*L42 -> 22700 | I45: 8300 | J45: =(((B45+C45)*$M$42)+(D45*$M$43)+(E45*$M$44))*0.99 -> 144252.9
G46: รวมเบิกไปแล้ว | I46: =SUM(I43:I45) -> 22700 | L46: การคิดเงินพิเศษ
G47: ค้างจ่ายค่าเที่ยว | H47: =H45-I46 -> 0 | L47: 150 | M47: 1000
B48: สรุปรายรับ จ่ายพนักงาน | C48: =C2 -> บุญมี ศรีสุระ | L48: 160 | M48: 2000
B49: รายรับ | L49: 170 | M49: 3000
B50: เงินเดือน | C50: =IF(F$45>120, E$1, E$1-2000) +E2 -> 10000 | L50: 180 | M50: 4000
B51: ค่าเที่ยว | C51: =H45 -> 22700 | L51: 190 | M51: 5000
B52: เงินพิเศษ | C52: =G45 -> 8000 | L52: 200 | M52: 6000
L53: 210 | M53: 7000
...

Sheet รายจ่ายอื่นๆ
A1: ว/ด/ป | B1: รายการ | C1: รายรับ | E1: รายจ่าย
C2: รายรับ | D2: VAT ขาย | E2: ซื้อของ | F2: ค่าแรง
A3: 244566 | B3: ส่งเอกสาร | E3: 63
A4: 13/5/2569 | B4: Sticker รถ | E4: 5800
A5: 16/5/2569 | B5: memory ไฟฉาย ที่ชาร์จไฟในรถ | E5: 2035
A6: 29/5/2569 | B6: Sticker รถ 514 | E6: 1000
A7: 31/5/2569 | B7: รางวัล sub ถึง 150ตู้ น้าดำ น้าเป็ด พัชร | E7: 6000
A27: รวม | E27: =sum(E3:E26) -> 14898

Sheet รายรับ-จ่าย จริง
A1: รายรับเดือน | B1: ธค | D1: วันที่ใบรับเงิน | E1: 26/11/68 | G1: รายรับ-จ่าย ภายในเดือน | J1: วันที่จ่ายเงินเดือน | K1: 31/12/68
A2: Triple T + JTS
A3: วันที่ | B3: เบอร์ | C3: จำนวนเที่ยว | D3: รายรับ | E3: รายจ่าย | G3: วันที่ | H3: เบอร์ | I3: จำนวนเที่ยว | J3: รายรับ | K3: รายจ่าย
A4: =$E$1 -> 26/11/68 | B4: 37 | C4: =template!F50 -> 0 | D4: 84575.1 | E4: =template!$B$41 -> 0 | G4: =$K$1 -> 31/12/68 | H4: 37 | I4: =template!$F$50 -> 0 | J4: =template!$J$50 -> 0 | K4: =template!$B$41 -> 0
A5: =$E$1 -> 26/11/68 | B5: 39 | D5: 80765 | E5: ='39 506 Bonbon'!$B$33 -> 95205 | G5: =$K$1 -> 31/12/68 | H5: 39 | I5: ='39 506 Bonbon'!$F$41 -> 197 | J5: ='39 506 Bonbon'!J$41 -> 126432.9 | K5: ='39 506 Bonbon'!$B$33 -> 95205
A6: =$E$1 -> 26/11/68 | B6: 47 | D6: 59753 | E6: ='47 507 จันทร์'!$B$34 -> 124360.05 | G6: =$K$1 -> 31/12/68 | H6: 47 | I6: ='47 507 จันทร์'!$F$41 -> 143 | J6: ='47 507 จันทร์'!$J$42 -> 147539.7 | K6: ='47 507 จันทร์'!$B$34 -> 124360.05
A7: =$E$1 -> 26/11/68 | B7: 48 | D7: 24144.1 | E7: ='48 508 นิค'!$B$34 -> 72751.45 | G7: =$K$1 -> 31/12/68 | H7: 48 | I7: ='48 508 นิค'!$F$42 -> 150 | J7: ='48 508 นิค'!$J$42 -> 95881.5 | K7: ='48 508 นิค'!$B$34 -> 72751.45
A8: =$E$1 -> 26/11/68 | B8: 501 | E8: ='501 เต่า'!$B$33 -> 104325 | G8: =$K$1 -> 31/12/68 | H8: 501 | I8: ='501 เต่า'!$F$41 -> 212 | J8: ='501 เต่า'!$J$41 -> 135342.9 | K8: ='501 เต่า'!$B$33 -> 104325
A9: =$E$1 -> 26/11/68 | B9: 502 | E9: ='502 ป๋า'!$B$34 -> 113005.4 | G9: =$K$1 -> 31/12/68 | H9: 502 | I9: ='502 ป๋า'!$F$42 -> 261 | J9: ='502 ป๋า'!$J$42 -> 166943.7 | K9: ='502 ป๋า'!$B$34 -> 113005.4
A10: =$E$1 -> 26/11/68 | B10: 503 | E10: ='503 ฟัก'!$B$37 -> 86215 | G10: =$K$1 -> 31/12/68 | H10: 503 | I10: ='503 ฟัก'!$F$45 -> 142 | J10: ='503 ฟัก'!$J$45 -> 90248.4 | K10: ='503 ฟัก'!$B$37 -> 86215
A11: =$E$1 -> 26/11/68 | B11: 504 | E11: ='504 ประจบ'!$B$37 -> 66346 | G11: =$K$1 -> 31/12/68 | H11: 504 | I11: ='504 ประจบ'!$F$45 -> 77 | J11: ='504 ประจบ'!$J$45 -> 48915.9 | K11: ='504 ประจบ'!$B$37 -> 66346
A12: =$E$1 -> 26/11/68 | B12: 505 | E12: ='505 เสริม เอ็ม บุญมี'!$B$37 -> 126858.5 | G12: =$K$1 -> 31/12/68 | H12: 505 | I12: ='505 เสริม เอ็ม บุญมี'!$F$45 -> 227 | J12: ='505 เสริม เอ็ม บุญมี'!$J$45 -> 144252.9 | K12: ='505 เสริม เอ็ม บุญมี'!$B$37 -> 126858.5
A13: =$E$1 -> 26/11/68 | G13: =$K$1 -> 31/12/68
A14: =$E$1 -> 26/11/68 | B14: อื่นๆ | E14: ='รายจ่ายอื่นๆ'!$E$27 -> 14898 | G14: =$K$1 -> 31/12/68 | H14: อื่นๆ | K14: ='รายจ่ายอื่นๆ'!$E$27 -> 14898
A15: รวม | D15: =SUM(D4:D10) -> 249237.2 | E15: =SUM(E4:E9) -> 509646.9 | G15: รวม | J15: =SUM(J4:J10) -> 762389.1 | K15: =SUM(K4:K14) -> 803964.4
A16: กำไร ขาดทุน | D16: =D15-E15 -> -260409.7 | G16: กำไร ขาดทุน | I16: =Sum(I4:I10) -> 1105 | J16: =J15-K15 -> -41575.3

Sheet ทะเบียน ประกัน
A2: เบอร์ | B2: ประกอบการ | C2: ทะเบียนหัว | D2: Chassis No. | E2: ทะเบียนหมดอายุ | F2: พรบ หมดอายุ | G2: ประกัน หมดอายุ | H2: ประกันสินค้า | I2: ทะเบียนหาง | J2: Chassis No. | K2: ทะเบียนหมดอายุ | L2: พรบ หมดอายุ | M2: ประกัน หมดอายุ | N2: ประกันสินค้า | O2: วันที่ทะเบียนหมดอายุ | P2: ประกัน | Q2: วันหมดอายุประกัน | R2: ถ่ายน้ำมันเครื่อง | S2: ถ่ายน้ำมันเกียร์
A3: 37 | C3: 72-3584 | D3: Mitsu FN215K50392 | E3: 30/09/69 | I3: 72-3585 | J3: 5374-PN34 | K3: 30/09/69 | O3: 30/09/69 | P3: ERGO | Q3: 25513
A4: 506 | C4: 74-5230 | D4: Mitsu Fuso MMJFM65F15C000690 | E4: 31/03/70 | F4: 31/03/70 (วิริยะ) | I4: 74-8395 | J4: P48-7198 | K4: 31/03/70 | L4: 31/03/70 (วิริยะ) | O4: 31/03/69, 31/12/68 | P4: ERGO | Q4: 13/06/69 | R4: 244624
A5: 507 | C5: 73-3382 | D5: Nissan CDA214M00380 | E5: 31/12/69 | F5: 31/12/69 (วิริยะ) | I5: 73-7154 | J5: SMM100447-0790 | K5: 31/12/69 | L5: 31/12/69 (วิริยะ) | O5: 31/12/68 | P5: ERGO | Q5: 25/01/69 | R5: 244625 | S5: 244625
A6: 508 | C6: 74-8394 | D6: Hino FM2PKPA-11344 | E6: 31/03/70 | F6: 31/03/70 (วิริยะ) | I6: 73-3384 | K6: 31/12/69 | L6: 31/12/69 (วิริยะ) | O6: 31/03/69 | P6: ERGO | Q6: 16/06/69 | R6: 244563
A7: 501 | C7: 74-8874 | D7: Hino FM2PKPA-13552 | E7: 30/06/69 | F7: 30/06/2569 (วิริยะ) | G7: 3/11/2569 (ไทยวิวัฒน์) | I7: 74-8875 | J7: SMM100236-0010 | K7: 30/06/69 | O7: 30/06/69 | P7: วิริยะ | Q7: 30/06/69 | R7: 244258
A8: 502 | C8: 74-9438 | D8: Isuzu GXZ23KZ247001842 | E8: 30/06/69 | F8: 30/06/2569 | G8: 28/08/2569 (ไทยวิวัฒน์) | H8: AXA | I8: 74-9697 | J8: P47-7704 | K8: 30/09/69 | O8: 26/06/69, 30/09/69 | P8: ไทยวิวัฒน์ | Q8: 28/08/69 | R8: 27/4/2569
A9: 503 | C9: 74-9437 | D9: Isuzu GXZ23KZ223000839 | E9: 30/06/69 | G9: 24/09/2569 (ERGO) | H9: AXA | I9: 74-7023 | J9: P50-8829 | K9: 31/12/69 | L9: 31/12/69 (วิริยะ) | O9: 30/06/69, 31/12/68 | P9: ERGO | Q9: 24/09/69
A10: 504 | C10: 75-0287 สป | D10: Isuzu GXZ23KZ2 47001795 (2013) | E10: 30/09/69 | F10: 244419 | G10: 3/11/2569 (ไทยวิวัฒน์) | H10: 19/01/2570 (AXA) | I10: 75-0288 สป | J10: PANUS PS2SC1220, P477705 | K10: 30/09/69 | M10: 3/11/2569 (ไทยวิวัฒน์) | N10: 19/01/2570 | P10: ไทยวิวัฒน์ | Q10: 244419
A11: 505 | C11: 75-0286 สป | D11: Isuzu GXZ23KZ2 47001843 (2007) | E11: 30/09/69 | F11: 244419 | G11: 3/11/2569 (ไทยวิวัฒน์) | H11: 17/01/2570 (AXA) | I11: 75-0289 สป | J11: PANUS PS2SC1220, P477690 | K11: 30/09/69 | L11: 244419 | M11: 3/11/2569 (ไทยวิวัฒน์) | N11: 17/01/2570 | P11: ไทยวิวัฒน์ / AXA | Q11: 244419 | R11: 13/10/2568
D18: ต่อทะเบียนและพรบ คันที่หมดอายุแล้ว | E18: ทะเบียนหมดอายุ
D25: ต่อทะเบียนและพรบ คันที่ใกล้หมดอายุแล้ว
C26: 501 | D26: 74-8874 | E26: 30/06/69
C27: 502 | D27: 74-9438 | E27: 30/06/69
C28: 503 | D28: 74-9437 | E28: 30/06/69
C29: หาง501 | D29: 74-8875 | E29: 30/06/69
D32: ประกันรถจะหมด
C33: 506 | D33: 74-5230 | E33: ERGO | F33: 13/06/69
C34: 508 | D34: 74-8394 | E34: ERGO | F34: 16/06/69
C35: 501 | D35: 74-8874 | E35: วิริยะ | F35: 30/06/69
C36: 507 | D36: 73-3382 | E36: ERGO | F36: 25/01/69
